2022-12-06 08:56:34,889 - Logger.py[line:32] - INFO: 自定义商品指数事件回溯模型定时任务执行失败,原因:(pymysql.err.OperationalError) (2003, "Can't connect to MySQL server on '192.168.11.253' (timed out)")
(Background on this error at: http://sqlalche.me/e/13/e3q8)
2022-12-06 08:59:14,522 - Logger.py[line:32] - INFO: 自定义商品指数事件回溯模型定时任务执行失败,原因:(pymysql.err.OperationalError) (1045, "Access denied for user 'root'@'DESKTOP-QQ6121O' (using password: YES)")
(Background on this error at: http://sqlalche.me/e/13/e3q8)
2022-12-06 08:59:47,481 - Logger.py[line:32] - INFO: 自定义商品指数事件回溯模型定时任务执行失败,原因:list index out of range
2022-12-06 08:59:55,856 - Logger.py[line:32] - INFO: 自定义商品指数事件回溯模型定时任务执行失败,原因:list index out of range
